<?xml version="1.0"?>
<!-- Revolute-Revolute Manipulator -->
<robot name="omron1s" xmlns:xacro="http://www.ros.org/wiki/xacro">

  <!-- Import all Gazebo-customization elements, including Gazebo colors -->
  <xacro:include filename="$(find omron1s_description)/urdf/omron1s.gazebo"/>
  <!-- Import Rviz colors -->
  <xacro:include filename="$(find omron1s_description)/urdf/materials.xacro"/>

  <!-- Used for fixing robot to Gazebo 'base_link' -->
  <link name="world"/>

  <joint name="fixed" type="fixed">
    <parent link="world"/>
    <child link="base_link"/>
  </joint>

  <link
    name="base_link">
    <inertial>
      <origin
        xyz="0.058756 -0.084662 0.1005"
        rpy="0 0 0" />
      <mass
        value="0.71125" />
      <inertia
        ixx="0.0032491"
        ixy="-2.2578E-22"
        ixz="9.8868E-22"
        iyy="0.0032491"
        iyz="-6.6907E-19"
        izz="0.0048171" />
    </inertial>
    <visual>
      <origin
        xyz="0 0 0"
        rpy="0 0 0" />
      <geometry>
        <mesh
          filename="file:///$(find omron1s_description)/meshes/base_link.STL" />
      </geometry>
      <material
        name="">
        <color
          rgba="0.79216 0.81961 0.93333 1" />
      </material>
    </visual>
    <collision>
      <origin
        xyz="0 0 0"
        rpy="0 0 0" />
      <geometry>
        <mesh
          filename="file:///$(find omron1s_description)/meshes/base_link.STL" />
      </geometry>
    </collision>
  </link>
  <link
    name="link1">
    <inertial>
      <origin
        xyz="2.08166817117217E-17 0.04 -0.0377780415986943"
        rpy="0 0 0" />
      <mass
        value="2.08761053730566" />
      <inertia
        ixx="0.00742870445718791"
        ixy="-6.84015806136404E-20"
        ixz="1.95156391047391E-18"
        iyy="0.00952055836647544"
        iyz="1.02543660202385E-19"
        izz="0.00422480958182635" />
    </inertial>
    <visual>
      <origin
        xyz="0 0 0"
        rpy="0 0 0" />
      <geometry>
        <mesh
          filename="file:///$(find omron1s_description)/meshes/link1.STL" />
      </geometry>
      <material
        name="">
        <color
          rgba="0.792156862745098 0.819607843137255 0.933333333333333 1" />
      </material>
    </visual>
    <collision>
      <origin
        xyz="0 0 0"
        rpy="0 0 0" />
      <geometry>
        <mesh
          filename="file:///$(find omron1s_description)/meshes/link1.STL" />
      </geometry>
    </collision>
  </link>
  <joint
    name="joint1"
    type="revolute">
    <origin
      xyz="0.0587564520357434 -0.0846616099911215 0.151979361094108"
      rpy="1.5707963267949 0 -2.77072298333055" />
    <parent
      link="base_link" />
    <child
      link="link1" />
    <axis
      xyz="0 1 0" />
    <limit
      lower="-3.14"
      upper="3.14"
      effort="500"
      velocity="6.28" />
    <dynamics damping="60.0" friction="4.0" />
  </joint>
  <link
    name="link2">
    <inertial>
      <origin
        xyz="-0.095000000000001 -2.77555756156289E-16 0.275"
        rpy="0 0 0" />
      <mass
        value="2.45132741228718" />
      <inertia
        ixx="0.0781860308173814"
        ixy="0"
        ixz="4.32325616278595E-18"
        iyy="0.0774228597300263"
        iyz="7.23162849047831E-17"
        izz="0.00178455750914138" />
    </inertial>
    <visual>
      <origin
        xyz="0 0 0"
        rpy="0 0 0" />
      <geometry>
        <mesh
          filename="file:///$(find omron1s_description)/meshes/link2.STL" />
      </geometry>
      <material
        name="">
        <color
          rgba="0.792156862745098 0.819607843137255 0.933333333333333 1" />
      </material>
    </visual>
    <collision>
      <origin
        xyz="0 0 0"
        rpy="0 0 0" />
      <geometry>
        <mesh
          filename="file:///$(find omron1s_description)/meshes/link2.STL" />
      </geometry>
    </collision>
  </link>
  <joint
    name="joint2"
    type="revolute">
    <origin
      xyz="0 0.0400000000000031 -0.0999999999999985"
      rpy="1.97667516838365 0 3.14159265358979" />
    <parent
      link="link1" />
    <child
      link="link2" />
    <axis
      xyz="1 0 0" />
    <limit
      lower="-3.14"
      upper="3.14"
      effort="500"
      velocity="6.28" />
    <dynamics damping="60.0" friction="4.0" />
  </joint>
  <link
    name="link3">
    <inertial>
      <origin
        xyz="-0.0449999999999999 -2.22044604925031E-16 0.275"
        rpy="0 0 0" />
      <mass
        value="2.45132741228718" />
      <inertia
        ixx="0.0781860308173814"
        ixy="-4.33680868994202E-18"
        ixz="6.39679281766448E-18"
        iyy="0.0774228597300263"
        iyz="9.83371370444353E-17"
        izz="0.00178455750914137" />
    </inertial>
    <visual>
      <origin
        xyz="0 0 0"
        rpy="0 0 0" />
      <geometry>
        <mesh
          filename="file:///$(find omron1s_description)/meshes/link3.STL" />
      </geometry>
      <material
        name="">
        <color
          rgba="0.792156862745098 0.819607843137255 0.933333333333333 1" />
      </material>
    </visual>
    <collision>
      <origin
        xyz="0 0 0"
        rpy="0 0 0" />
      <geometry>
        <mesh
          filename="file:///$(find omron1s_description)/meshes/link3.STL" />
      </geometry>
    </collision>
  </link>
  <joint
    name="joint3"
    type="revolute">
    <origin
      xyz="0 0 0.55"
      rpy="1.75653072975658 0 0" />
    <parent
      link="link2" />
    <child
      link="link3" />
    <axis
      xyz="1 0 0" />
    <limit
      lower="-3.14"
      upper="3.14"
      effort="500"
      velocity="6.28" />
    <dynamics damping="60.0" friction="4.0" />
  </joint>
  <link
    name="link4">
    <inertial>
      <origin
        xyz="-0.048723 -1.4225E-08 2.0409E-08"
        rpy="0 0 0" />
      <mass
        value="0.95838" />
      <inertia
        ixx="0.00129"
        ixy="8.6782E-10"
        ixz="-2.1532E-09"
        iyy="0.0016328"
        iyz="-9.2513E-10"
        izz="0.0017839" />
    </inertial>
    <visual>
      <origin
        xyz="0 0 0"
        rpy="0 0 0" />
      <geometry>
        <mesh
          filename="file:///$(find omron1s_description)/meshes/link4.STL" />
      </geometry>
      <material
        name="">
        <color
          rgba="0.79216 0.81961 0.93333 1" />
      </material>
    </visual>
    <collision>
      <origin
        xyz="0 0 0"
        rpy="0 0 0" />
      <geometry>
        <mesh
          filename="file:///$(find omron1s_description)/meshes/link4.STL" />
      </geometry>
    </collision>
  </link>
  <joint
    name="joint4"
    type="revolute">
    <origin
      xyz="0 0 0.55"
      rpy="0.535953139821402 0 -3.14159265358979" />
    <parent
      link="link3" />
    <child
      link="link4" />
    <axis
      xyz="1 0 0" />
    <limit
      lower="-3.14"
      upper="3.14"
      effort="500"
      velocity="6.28" />
    <dynamics damping="60.0" friction="4.0" />

  </joint>

    <!-- ROS2 CONTROL REAL -->
    <!-- <ros2_control name="Omron1SHardware" type="system">
    
      <hardware>
        <plugin>omron1s_hardware/Omron1SHardware</plugin>
        <param name="interface_name">enp2s0</param>
        <param name="use_dummy">false</param>
      </hardware>
    
      <joint name="joint1">
        <param name="id">1</param>
        <command_interface name="position"/>
        <state_interface name="position"/>
      </joint>

      <joint name="joint2">
        <param name="id">2</param>
        <command_interface name="position"/>
        <state_interface name="position"/>
      </joint>

      <joint name="joint3">
        <param name="id">3</param>
        <command_interface name="position"/>
        <state_interface name="position"/>
      </joint>

      <joint name="joint4">
        <param name="id">4</param>
        <command_interface name="position"/>
        <state_interface name="position"/>
      </joint>
    
    </ros2_control> -->

    <!-- ROS2 CONTROL SIMULATION -->
    <ros2_control name="GazeboSystem" type="system">
			<hardware>
				<plugin>gazebo_ros2_control/GazeboSystem</plugin>
	    </hardware>

	    	<joint name="joint1">
	    		<command_interface name="position">
	    			<param name="min">-3.14</param>
	    			<param name="max">3.14</param>
	    		</command_interface>
	    		<state_interface name="position"/>
	    		<state_interface name="velocity"/>
	    		<state_interface name="effort"/>
	    	</joint>

	    	<joint name="joint2">
	    		<command_interface name="position">
	    			<param name="min">-3.14</param>
	    			<param name="max">3.14</param>
	    		</command_interface>
	    		<state_interface name="position"/>
	    		<state_interface name="velocity"/>
	    		<state_interface name="effort"/>
	    	</joint>

	    	<joint name="joint3">
	    		<command_interface name="position">
	    			<param name="min">-3.14</param>
	    			<param name="max">3.14</param>
	    		</command_interface>
	    		<state_interface name="position"/>
	    		<state_interface name="velocity"/>
	    		<state_interface name="effort"/>
	    	</joint>

	    	<joint name="joint4">
	    		<command_interface name="position">
	    			<param name="min">-3.14</param>
	    			<param name="max">3.14</param>
	    		</command_interface>
	    		<state_interface name="position"/>
	    		<state_interface name="velocity"/>
	    		<state_interface name="effort"/>
	    	</joint>

	  	</ros2_control>

		<gazebo>
			<plugin name="gazebo_ros2_control" filename="libgazebo_ros2_control.so">
        		<!--<robot_sim_type>gazebo_ros2_control/DefaultRobotHWSim</robot_sim_type> -->
				<!-- <robot_sim_type>gazebo_ros2_control/GazeboSystem</robot_sim_type> -->
				<parameters>$(find omron1s_hwi)/config/controller_configuration.yaml</parameters>
		  </plugin>
		</gazebo>


    <!-- TRANSMISSION -->
    <!-- Transmission 1 -->
		<transmission name="tran1">
			<type>transmission_interface/SimpleTransmission</type>
			<joint name="joint1">
				<hardwareInterface>hardware_interface/PositionJointInterface</hardwareInterface>
			</joint>
			<actuator name="motor1">
				<hardwareInterface>hardware_interface/PositionJointInterface</hardwareInterface>
				<mechanicalReduction>1</mechanicalReduction>
			</actuator>
		</transmission>
		<!-- Transmission 2 -->
		<transmission name="tran2">
			<type>transmission_interface/SimpleTransmission</type>
			<joint name="joint2">
				<hardwareInterface>hardware_interface/PositionJointInterface</hardwareInterface>
			</joint>
			<actuator name="motor2">
				<hardwareInterface>hardware_interface/PositionJointInterface</hardwareInterface>
				<mechanicalReduction>1</mechanicalReduction>
			</actuator>
		</transmission>
		<!-- Transmission 3 -->
		<transmission name="tran3">
			<type>transmission_interface/SimpleTransmission</type>
			<joint name="joint3">
				<hardwareInterface>hardware_interface/PositionJointInterface</hardwareInterface>
			</joint>
			<actuator name="motor3">
				<hardwareInterface>hardware_interface/PositionJointInterface</hardwareInterface>
				<mechanicalReduction>1</mechanicalReduction>
			</actuator>
		</transmission>
		<!-- Transmission 4 -->
		<transmission name="tran4">
			<type>transmission_interface/SimpleTransmission</type>
			<joint name="joint4">
				<hardwareInterface>hardware_interface/PositionJointInterface</hardwareInterface>
			</joint>
			<actuator name="motor4">
				<hardwareInterface>hardware_interface/PositionJointInterface</hardwareInterface>
				<mechanicalReduction>1</mechanicalReduction>
			</actuator>
		</transmission>

</robot>
