<?xml version="1.0"?>
<!-- Revolute-Revolute Manipulator -->
<robot name="omron1s" xmlns:xacro="http://www.ros.org/wiki/xacro">

  <!-- Import all Gazebo-customization elements, including Gazebo colors -->
  <xacro:include filename="$(find omron1s_description)/urdf/omron1s.gazebo"/>
  <!-- Import Rviz colors -->
  <xacro:include filename="$(find omron1s_description)/urdf/materials.xacro"/>

  <!-- Used for fixing robot to Gazebo 'base_link' -->
  <link name="world"/>

  <joint name="fixed" type="fixed">
    <parent link="world"/>
    <child link="base_link"/>
  </joint>

  <link
    name="base_link">
    <inertial>
      <origin
        xyz="0.058756 0.1005 0.084662"
        rpy="0 0 0" />
      <mass
        value="0.71125" />
      <inertia
        ixx="0.0032491"
        ixy="1.0152E-21"
        ixz="2.3749E-22"
        iyy="0.0048171"
        iyz="7.6509E-19"
        izz="0.0032491" />
    </inertial>
    <visual>
      <origin
        xyz="0 0 0"
        rpy="0 0 0" />
      <geometry>
        <mesh
          filename="file:///$(find omron1s_description)/meshes/base_link.STL" />
      </geometry>
      <material
        name="">
        <color
          rgba="0.79216 0.81961 0.93333 1" />
      </material>
    </visual>
    <collision>
      <origin
        xyz="0 0 0"
        rpy="0 0 0" />
      <geometry>
        <mesh
          filename="file:///$(find omron1s_description)/meshes/base_link.STL" />
      </geometry>
    </collision>
  </link>
  <link
    name="link1">
    <inertial>
      <origin
        xyz="-2.7756E-17 0.04 -0.037778"
        rpy="0 0 0" />
      <mass
        value="2.0876" />
      <inertia
        ixx="0.0074287"
        ixy="-4.9804E-20"
        ixz="-4.391E-18"
        iyy="0.0095206"
        iyz="1.2084E-19"
        izz="0.0042248" />
    </inertial>
    <visual>
      <origin
        xyz="0 0 0"
        rpy="0 0 0" />
      <geometry>
        <mesh
          filename="file:///$(find omron1s_description)/meshes/link1.STL" />
      </geometry>
      <material
        name="">
        <color
          rgba="0.79216 0.81961 0.93333 1" />
      </material>
    </visual>
    <collision>
      <origin
        xyz="0 0 0"
        rpy="0 0 0" />
      <geometry>
        <mesh
          filename="file:///$(find omron1s_description)/meshes/link1.STL" />
      </geometry>
    </collision>
  </link>
  <joint
    name="joint1"
    type="revolute">
    <origin
      xyz="0.058756 -0.084662 0.15198"
      rpy="1.5708 0 -2.9046" />
    <parent
      link="base_link" />
    <child
      link="link1" />
    <axis
      xyz="0 1 0" />
    <limit
      lower="-6.28"
      upper="6.28"
      effort="500"
      velocity="6.28" />
    <dynamics
      damping="200"
      friction="50" />
  </joint>
  <link
    name="link2">
    <inertial>
      <origin
        xyz="-0.022244 -3.8858E-16 0.275"
        rpy="0 0 0" />
      <mass
        value="2.4513" />
      <inertia
        ixx="0.078186"
        ixy="-1.7347E-18"
        ixz="-3.5521E-17"
        iyy="0.077423"
        iyz="1.0148E-16"
        izz="0.0017846" />
    </inertial>
    <visual>
      <origin
        xyz="0 0 0"
        rpy="0 0 0" />
      <geometry>
        <mesh
          filename="file:///$(find omron1s_description)/meshes/link2.STL" />
      </geometry>
      <material
        name="">
        <color
          rgba="0.79216 0.81961 0.93333 1" />
      </material>
    </visual>
    <collision>
      <origin
        xyz="0 0 0"
        rpy="0 0 0" />
      <geometry>
        <mesh
          filename="file:///$(find omron1s_description)/meshes/link2.STL" />
      </geometry>
    </collision>
  </link>
  <joint
    name="joint2"
    type="revolute">
    <origin
      xyz="0.072756 0.04 -0.1"
      rpy="1.1256 0 3.1416" />
    <parent
      link="link1" />
    <child
      link="link2" />
    <axis
      xyz="1 0 0" />
    <limit
      lower="-6.28"
      upper="6.28"
      effort="500"
      velocity="6.28" />
    <dynamics
      damping="200"
      friction="50" />
  </joint>
  <link
    name="link3">
    <inertial>
      <origin
        xyz="0.027756 8.8818E-16 0.275"
        rpy="0 0 0" />
      <mass
        value="2.4513" />
      <inertia
        ixx="0.078186"
        ixy="-4.3368E-19"
        ixz="-2.1467E-17"
        iyy="0.077423"
        iyz="5.9902E-17"
        izz="0.0017846" />
    </inertial>
    <visual>
      <origin
        xyz="0 0 0"
        rpy="0 0 0" />
      <geometry>
        <mesh
          filename="file:///$(find omron1s_description)/meshes/link3.STL" />
      </geometry>
      <material
        name="">
        <color
          rgba="0.79216 0.81961 0.93333 1" />
      </material>
    </visual>
    <collision>
      <origin
        xyz="0 0 0"
        rpy="0 0 0" />
      <geometry>
        <mesh
          filename="file:///$(find omron1s_description)/meshes/link3.STL" />
      </geometry>
    </collision>
  </link>
  <joint
    name="joint3"
    type="revolute">
    <origin
      xyz="0 0 0.55"
      rpy="2.4678 0 0" />
    <parent
      link="link2" />
    <child
      link="link3" />
    <axis
      xyz="1 0 0" />
    <limit
      lower="-6.28"
      upper="6.28"
      effort="500"
      velocity="6.28" />
    <dynamics
      damping="200"
      friction="50" />
  </joint>
  <link
    name="link4">
    <inertial>
      <origin
        xyz="0.01137 -1.4733E-08 2.4175E-08"
        rpy="0 0 0" />
      <mass
        value="0.95052" />
      <inertia
        ixx="0.001281"
        ixy="8.7095E-10"
        ixz="-2.2716E-09"
        iyy="0.0016268"
        iyz="-9.4098E-10"
        izz="0.0017739" />
    </inertial>
    <visual>
      <origin
        xyz="0 0 0"
        rpy="0 0 0" />
      <geometry>
        <mesh
          filename="file:///$(find omron1s_description)/meshes/link4.STL" />
      </geometry>
      <material
        name="">
        <color
          rgba="0.79216 0.81961 0.93333 1" />
      </material>
    </visual>
    <collision>
      <origin
        xyz="0 0 0"
        rpy="0 0 0" />
      <geometry>
        <mesh
          filename="file:///$(find omron1s_description)/meshes/link4.STL" />
      </geometry>
    </collision>
  </link>
  <joint
    name="joint4"
    type="revolute">
    <origin
      xyz="0.13276 0 0.55"
      rpy="0.45181 0 -3.1416" />
    <parent
      link="link3" />
    <child
      link="link4" />
    <axis
      xyz="-1 0 0" />
    <limit
      lower="-6.28"
      upper="6.28"
      effort="500"
      velocity="6.28" />
    <dynamics
      damping="200"
      friction="50" />
  </joint>
  <link
    name="gripper">
    <inertial>
      <origin
        xyz="0.037654 0.05165 0.064091"
        rpy="0 0 0" />
      <mass
        value="0.25674" />
      <inertia
        ixx="0.00015569"
        ixy="1.8365E-07"
        ixz="2.3502E-07"
        iyy="0.00027921"
        iyz="9.4751E-08"
        izz="0.00021782" />
    </inertial>
    <visual>
      <origin
        xyz="0 0 0"
        rpy="0 0 0" />
      <geometry>
        <mesh
          filename="file:///$(find omron1s_description)/meshes/gripper.STL" />
      </geometry>
      <material
        name="">
        <color
          rgba="0.75294 0.75294 0.75294 1" />
      </material>
    </visual>
    <collision>
      <origin
        xyz="0 0 0"
        rpy="0 0 0" />
      <geometry>
        <mesh
          filename="file:///$(find omron1s_description)/meshes/gripper.STL" />
      </geometry>
    </collision>
  </link>
  <joint
    name="gripper_joint"
    type="fixed">
    <origin
      xyz="0.037522 0.15383 -0.064188"
      rpy="0 0 3.1416" />
    <parent
      link="link4" />
    <child
      link="gripper" />
    <axis
      xyz="0 0 0" />
  </joint>

  <link name="gripper_tip"/>
  
  <joint
    name="gripper_tip_joint"
    type="fixed">
    <origin
      xyz="0.0 0.0 0.0"
      rpy="0 0 0" />
    <parent
      link="gripper" />
    <child
      link="gripper_tip" />
    <axis
      xyz="0 0 0" />
  </joint>


  <!-- ROS2 CONTROL-->
  <ros2_control name="Omron1SControl" type="system">

    <!-- <hardware>
      <plugin>omron1s_hardware/Omron1SHardware</plugin>
      <param name="interface_name">enp2s0</param>
      <param name="use_dummy">false</param>
    </hardware> -->

    <hardware>
      <plugin>gazebo_ros2_control/GazeboSystem</plugin>
    </hardware>

      <joint name="joint1">
        <param name="id">1</param>
        <command_interface name="position">
          <param name="min">-3.14</param>
          <param name="max">3.14</param>
        </command_interface>
        <state_interface name="position"/>
        <state_interface name="velocity"/>
        <state_interface name="effort"/>
      </joint>

      <joint name="joint2">
        <param name="id">2</param>
        <command_interface name="position">
          <param name="min">-3.14</param>
          <param name="max">3.14</param>
        </command_interface>
        <state_interface name="position"/>
        <state_interface name="velocity"/>
        <state_interface name="effort"/>
      </joint>

      <joint name="joint3">
        <param name="id">3</param>
        <command_interface name="position">
          <param name="min">-3.14</param>
          <param name="max">3.14</param>
        </command_interface>
        <state_interface name="position"/>
        <state_interface name="velocity"/>
        <state_interface name="effort"/>
      </joint>

      <joint name="joint4">
        <param name="id">4</param>
        <command_interface name="position">
          <param name="min">-3.14</param>
          <param name="max">3.14</param>
        </command_interface>
        <state_interface name="position"/>
        <state_interface name="velocity"/>
        <state_interface name="effort"/>
      </joint>

    </ros2_control>

  <gazebo>
    <plugin name="gazebo_ros2_control" filename="libgazebo_ros2_control.so">
          <!--<robot_sim_type>gazebo_ros2_control/DefaultRobotHWSim</robot_sim_type> -->
      <!-- <robot_sim_type>gazebo_ros2_control/GazeboSystem</robot_sim_type> -->
      <robot_sim_type>gazebo_ros2_control/GazeboSystem</robot_sim_type>
      <parameters>$(find omron1s_hwi)/config/controller_configuration.yaml</parameters>
    </plugin>
  </gazebo>


  <!-- TRANSMISSION -->
  <!-- Transmission 1 -->
  <transmission name="tran1">
    <type>transmission_interface/SimpleTransmission</type>
    <joint name="joint1">
      <hardwareInterface>hardware_interface/PositionJointInterface</hardwareInterface>
    </joint>
    <actuator name="motor1">
      <hardwareInterface>hardware_interface/PositionJointInterface</hardwareInterface>
      <mechanicalReduction>1</mechanicalReduction>
    </actuator>
  </transmission>
  <!-- Transmission 2 -->
  <transmission name="tran2">
    <type>transmission_interface/SimpleTransmission</type>
    <joint name="joint2">
      <hardwareInterface>hardware_interface/PositionJointInterface</hardwareInterface>
    </joint>
    <actuator name="motor2">
      <hardwareInterface>hardware_interface/PositionJointInterface</hardwareInterface>
      <mechanicalReduction>1</mechanicalReduction>
    </actuator>
  </transmission>
  <!-- Transmission 3 -->
  <transmission name="tran3">
    <type>transmission_interface/SimpleTransmission</type>
    <joint name="joint3">
      <hardwareInterface>hardware_interface/PositionJointInterface</hardwareInterface>
    </joint>
    <actuator name="motor3">
      <hardwareInterface>hardware_interface/PositionJointInterface</hardwareInterface>
      <mechanicalReduction>1</mechanicalReduction>
    </actuator>
  </transmission>
  <!-- Transmission 4 -->
  <transmission name="tran4">
    <type>transmission_interface/SimpleTransmission</type>
    <joint name="joint4">
      <hardwareInterface>hardware_interface/PositionJointInterface</hardwareInterface>
    </joint>
    <actuator name="motor4">
      <hardwareInterface>hardware_interface/PositionJointInterface</hardwareInterface>
      <mechanicalReduction>1</mechanicalReduction>
    </actuator>
  </transmission>

</robot>
